# Lecture 17: Templates, STL, Exceptions

Last Time

# Template stack class

```c++
template <typename T>
class Stack {
  int size;
  int capacity;
  T *contents;
public:
  void push (T x){ ... }
  T top(){ ... }
  void pop() { ... }
  ~Stack(){ ... }
}

stack <int> s1;
s1.push;

stack <std::string> s2;
s2.push("...");
```

# Template List class

```c++
template <typename T>
class List{
  struct Node{
    T data;
    Node *next;
  };
  Node *thelist = nullptr;

public:
  class Iterator{
    Node *curr;
    Iterator(...){...}; //ctor is private
  public:
    T &opeartor*() {...}
    Iterator &operator++(){...}
    friend class List<T>;
  };

  T ith(int i){...}
  void addToFront(T &t){...}
};

int main(){
  List <int> l1;
  l1.addToFront(i);
  for(List<int>::iterator it = l1.begin(); it!=l1.end(); ++it){
    cout << *it << endl;
  }
  List<List<int>> l2;
  l2.addToFront(l1);
}
```

# STL: Standard Template Library

std::vector - dynamically resizing array

```c++
#include <vector>

std::vector<int>
v{4,5};  //[4,5]
v.emplace_back(6); //[4,5,6]
vector<int> v1(4,5); //[5,5,5,5,5]

//Four ways to print
for(int i = 0; i < v.size(); ++i){
  cout << v[i] << endl;
}

for(vector<int>::iterator it = v.begin(); it != v.end(); ++it){
  cout << *it << endl;
}

for(auto n : v){
  cout << n << endl;
}

for(vector<int>::reverse_iterator rit=v.rbegin(); rit != v.rend(); ++rit){

}

v.pop_back(); //remove last elem

Many STL methods take iterators as parameters

auto it = v.erase(v.begin()) // remove first
v.erase(it);
v.erase(v.end - 1);
```

```c++
v[i] //- ith element -- unchecked access, if it is out of range behaviour is undefined

v.at(i) //-checked access, if i is out of range, an exception is thrown
```

# Exceptions

Go to c++/exceptions/rangeError.cc for example
   to c++/exceptions/rangeErrorCaught.cc

An exception will pop things off the stack frame until the error is caught.

When an exception occurs, the program begins to look for a catch black. This might cause stack frames to be popped off.

- if a catch block is found, code resumes there

Error recovery can be done in stages
```c++
try{

} catch (Some Exn e) {
  //can throw another exception
  //1. throw SomeUnrelatedExn{}
  //2. throw e; //throw the same exception
  //3. throw; //in 2 we catch by value, exception subclass gets sliced
}
```

All c++ library exceptions inherit from exception class
- in c++ you can throw anything ints, strings,
- our own exceptions need not inherit from the classes

Thus you can do:
```c++
try{

} catch (...){
  //catches everything
}
```
